Failure # 1 (occurred at 2021-07-27_11-07-21)
Traceback (most recent call last):
  File "/cluster/home/samuelbe/.local/lib/python3.8/site-packages/ray/tune/trial_runner.py", line 726, in _process_trial
    decision = self._process_trial_result(trial, result)
  File "/cluster/home/samuelbe/.local/lib/python3.8/site-packages/ray/tune/trial_runner.py", line 766, in _process_trial_result
    self._validate_result_metrics(flat_result)
  File "/cluster/home/samuelbe/.local/lib/python3.8/site-packages/ray/tune/trial_runner.py", line 875, in _validate_result_metrics
    raise ValueError(
ValueError: Trial returned a result which did not include the specified metric(s) `val_accuracy` that `tune.run()` expects. Make sure your calls to `tune.report()` include the metric, or set the TUNE_DISABLE_STRICT_METRIC_CHECKING environment variable to 1. Result: {'loss': 0.6519971489906311, 'acc': 0.7352877855300903, 'val_iou': 0.21668392419815063, 'time_this_iter_s': 73.87567448616028, 'done': False, 'timesteps_total': None, 'episodes_total': None, 'training_iteration': 1, 'experiment_id': '5344684dd9fe4a0795d8be8fd5840a7d', 'date': '2021-07-27_11-07-21', 'timestamp': 1627376841, 'time_total_s': 73.87567448616028, 'pid': 11626, 'hostname': 'lo-s4-016', 'node_ip': '10.204.3.66', 'time_since_restore': 73.87567448616028, 'timesteps_since_restore': 0, 'iterations_since_restore': 1, 'trial_id': '3d166_00003', 'config/model_name': 'attUnet', 'config/lr': 0.09835650565384976, 'config/loss_fn': 'dice_loss', 'config/batch_size': 2, 'config/num_epochs': 10, 'config/patch_size': 256, 'config/mode': 'patch_random', 'config/blend_mode': 'weighted_average', 'config/noise': False}

